2025-06-04 06:31:02 - INFO - [main] - 🎬 FX自動エントリーシステム開始
2025-06-04 06:31:02 - INFO - [main] - 📁 ログディレクトリ: C:\Users\beru\Dropbox\006_TRADE\historycal\bot_saxo\log
2025-06-04 06:31:02 - INFO - [__init__] - ================================================================================
2025-06-04 06:31:02 - INFO - [__init__] - 🚀 FX自動エントリーシステム起動
2025-06-04 06:31:02 - INFO - [__init__] - ================================================================================
2025-06-04 06:31:02 - DEBUG - [__init__] - システム設定:
2025-06-04 06:31:02 - DEBUG - [__init__] -   - 最大ポジション数: 5
2025-06-04 06:31:02 - DEBUG - [__init__] -   - 1取引リスク: 2.0%
2025-06-04 06:31:02 - DEBUG - [__init__] -   - デフォルト取引量: 10,000通貨
2025-06-04 06:31:02 - INFO - [_initialize_system] - 📋 システム初期化を開始します...
2025-06-04 06:31:02 - DEBUG - [_initialize_system] - 1/3: アカウント情報取得中...
2025-06-04 06:31:02 - DEBUG - [_get_account_info] - API呼び出し: /port/v1/accounts/me
2025-06-04 06:31:02 - DEBUG - [_new_conn] - Starting new HTTPS connection (1): gateway.saxobank.com:443
2025-06-04 06:31:04 - DEBUG - [_make_request] - https://gateway.saxobank.com:443 "GET /sim/openapi/port/v1/accounts/me HTTP/1.1" 401 0
2025-06-04 06:31:04 - DEBUG - [_get_account_info] - アカウント情報レスポンス: 401
2025-06-04 06:31:04 - ERROR - [_get_account_info] - アカウント取得失敗: 401
2025-06-04 06:31:04 - ERROR - [_get_account_info] - レスポンス: 
2025-06-04 06:31:04 - ERROR - [_get_account_info] - アカウント情報取得エラー: アカウント取得失敗: 401
2025-06-04 06:31:04 - ERROR - [_initialize_system] - ❌ システム初期化エラー: アカウント取得失敗: 401
2025-06-04 06:31:04 - ERROR - [_initialize_system] - 初期化エラーの詳細:
Traceback (most recent call last):
  File "C:\Users\beru\Dropbox\006_TRADE\historycal\bot_saxo\bot_saxo.py", line 135, in _initialize_system
    self._get_account_info()
  File "C:\Users\beru\Dropbox\006_TRADE\historycal\bot_saxo\bot_saxo.py", line 181, in _get_account_info
    raise Exception(f"アカウント取得失敗: {response.status_code}")
Exception: アカウント取得失敗: 401
2025-06-04 06:31:04 - ERROR - [main] - システムエラー: アカウント取得失敗: 401
2025-06-04 06:31:04 - ERROR - [main] - システムエラーの詳細:
Traceback (most recent call last):
  File "C:\Users\beru\Dropbox\006_TRADE\historycal\bot_saxo\bot_saxo.py", line 762, in main
    fx_system = FXAutoEntrySystem()
  File "C:\Users\beru\Dropbox\006_TRADE\historycal\bot_saxo\bot_saxo.py", line 126, in __init__
    self._initialize_system()
  File "C:\Users\beru\Dropbox\006_TRADE\historycal\bot_saxo\bot_saxo.py", line 135, in _initialize_system
    self._get_account_info()
  File "C:\Users\beru\Dropbox\006_TRADE\historycal\bot_saxo\bot_saxo.py", line 181, in _get_account_info
    raise Exception(f"アカウント取得失敗: {response.status_code}")
Exception: アカウント取得失敗: 401
