2025-05-29 06:31:04 - ERROR - [_get_account_info] - アカウント取得失敗: 401
2025-05-29 06:31:04 - ERROR - [_get_account_info] - レスポンス: 
2025-05-29 06:31:04 - ERROR - [_get_account_info] - アカウント情報取得エラー: アカウント取得失敗: 401
2025-05-29 06:31:04 - ERROR - [_initialize_system] - ❌ システム初期化エラー: アカウント取得失敗: 401
2025-05-29 06:31:04 - ERROR - [_initialize_system] - 初期化エラーの詳細:
Traceback (most recent call last):
  File "C:\Users\beru\Dropbox\006_TRADE\historycal\bot_saxo\bot_saxo.py", line 135, in _initialize_system
    self._get_account_info()
  File "C:\Users\beru\Dropbox\006_TRADE\historycal\bot_saxo\bot_saxo.py", line 181, in _get_account_info
    raise Exception(f"アカウント取得失敗: {response.status_code}")
Exception: アカウント取得失敗: 401
2025-05-29 06:31:04 - ERROR - [main] - システムエラー: アカウント取得失敗: 401
2025-05-29 06:31:04 - ERROR - [main] - システムエラーの詳細:
Traceback (most recent call last):
  File "C:\Users\beru\Dropbox\006_TRADE\historycal\bot_saxo\bot_saxo.py", line 762, in main
    fx_system = FXAutoEntrySystem()
  File "C:\Users\beru\Dropbox\006_TRADE\historycal\bot_saxo\bot_saxo.py", line 126, in __init__
    self._initialize_system()
  File "C:\Users\beru\Dropbox\006_TRADE\historycal\bot_saxo\bot_saxo.py", line 135, in _initialize_system
    self._get_account_info()
  File "C:\Users\beru\Dropbox\006_TRADE\historycal\bot_saxo\bot_saxo.py", line 181, in _get_account_info
    raise Exception(f"アカウント取得失敗: {response.status_code}")
Exception: アカウント取得失敗: 401
